(1)

Ran 3 tests in 0.000s

OK

(2) broken

theia@theiadocker:/home/project$ python3 test_mymodule.py
F..
======================================================================
FAIL: test1 (__main__.TestAdd)
----------------------------------------------------------------------
Traceback (most recent call last):
  File "/home/project/test_mymodule.py", line 47, in test1
    self.assertEqual(add(2,4),6)
AssertionError: 7 != 6

----------------------------------------------------------------------
Ran 3 tests in 0.000s

FAILED (failures=1)